Workbook

Sheet 问题代码结构
B2: 长度 | C2: 8位
B3: 结构 | C3: 2位报销单类型+2位会议类型+2位费用类型+2位问题类型
B5: 第1~2位 | C5: 根据报销单【单据名称】
B6: 代码 | C6: 报销单类型
B7: EN | C7: 个人日常和差旅（含小沟会）报销单
B8: MN | C8: 学术会议报销单
B10: 第3~4位 | C10: 根据费用明细【弹性字段7】
B11: 代码 | C11: 会议类型 | D11: 报销单类型
B12: 00 | C12: 个人 | D12: 个人日常
B13: 01 | C13: 学术论坛 | D13: 学术会议
B14: 02 | C14: 患者教育 | D14: 学术会议
B15: 03 | C15: 院内会 | D15: 学术会议
B16: 04 | C16: 多学科专家研讨会 | D16: 学术会议
B17: 05 | C17: 三方会-支持 | D17: 学术会议
B18: 06 | C18: 培训会 | D18: 学术会议
B19: 07 | C19: 临床研究-临床试验启动会 | D19: 学术会议
B20: 08 | C20: 专家咨询会 | D20: 学术会议
B22: 第5~6位 | C22: 根据费用明细【费用类型】
B23: 00 | C23: 通用
B25: Fee Type | C25: General通用问题适用于同一会议类型下的所有问题类型
B27: Fee Type Code | C27: Fee Type Description | D27: Meeting Code | E27: 会议类型 | F27: Expense Code | G27: 费用类型
B28: General00 | C28: 个人-通用 | D28: 00 | E28: 个人 | F28: 00 | G28: 通用
B29: General01 | C29: 学术论坛-通用 | D29: 01 | E29: 学术论坛 | F29: 00 | G29: 通用
B30: General02 | C30: 患者教育-通用 | D30: 02 | E30: 患者教育 | F30: 00 | G30: 通用
B31: General03 | C31: 院内会-通用 | D31: 03 | E31: 院内会 | F31: 00 | G31: 通用
B32: General04 | C32: 多学科专家研讨会-通用 | D32: 04 | E32: 多学科专家研讨会 | F32: 00 | G32: 通用
B33: General05 | C33: 三方会-支持-通用 | D33: 05 | E33: 三方会-支持 | F33: 00 | G33: 通用
B34: General06 | C34: 培训会-通用 | D34: 06 | E34: 培训会 | F34: 00 | G34: 通用
B35: General07 | C35: 临床研究-临床试验启动会-通用 | D35: 07 | E35: 临床研究-临床试验启动会 | F35: 00 | G35: 通用
B36: General08 | C36: 专家咨询会-通用 | D36: 08 | E36: 专家咨询会 | F36: 00 | G36: 通用

Sheet Fee Type
A1: Fee Type Code | B1: Fee Type Description | C1: Meeting Code | D1: 会议类型 | E1: Expense Code | F1: 费用类型
A2: General00 | B2: 个人-通用 | C2: 00 | D2: 个人 | E2: 00 | F2: 通用
A3: General01 | B3: 学术论坛-通用 | C3: 01 | D3: 学术论坛 | E3: 00 | F3: 通用
A4: General02 | B4: 患者教育-通用 | C4: 02 | D4: 患者教育 | E4: 00 | F4: 通用
A5: General03 | B5: 院内会-通用 | C5: 03 | D5: 院内会 | E5: 00 | F5: 通用
A6: General04 | B6: 多学科专家研讨会-通用 | C6: 04 | D6: 多学科专家研讨会 | E6: 00 | F6: 通用
A7: General05 | B7: 三方会-支持-通用 | C7: 05 | D7: 三方会-支持 | E7: 00 | F7: 通用
A8: General06 | B8: 培训会-通用 | C8: 06 | D8: 培训会 | E8: 00 | F8: 通用
A9: General07 | B9: 临床研究-临床试验启动会-通用 | C9: 07 | D9: 临床研究-临床试验启动会 | E9: 00 | F9: 通用
A10: General08 | B10: 专家咨询会-通用 | C10: 08 | D10: 专家咨询会 | E10: 00 | F10: 通用
A11: 0001 | B11: 个人-月度交通费（销售/SMO/CO) | C11: 00 | D11: 个人 | E11: 01 | F11: 月度交通费（销售/SMO/CO)
A12: 0002 | B12: 个人-交通费-市内 | C12: 00 | D12: 个人 | E12: 02 | F12: 交通费-市内
... A92: 0812 | B92: 专家咨询会-专家咨询费 | C92: 08 | D92: 专家咨询会 | E92: 12 | F92: 专家咨询费

Sheet 个人
A1: Fee Type Code | B1: Fee Type Description | C1: Problem Code | D1: Meeting Code | E1: 会议类型 | F1: Expense Code | G1: 费用类型 | H1: Issue Code | I1: 问题类型 | J1: SOP描述 | K1: 标准处理方法
A2: =IF(F2="00","General"&INDEX(问题代码结构!$B$12:$B$20,MATCH($E2,问题代码结构!$C$12:$C$20,0)),D2&F2) -> 0001 | B2: =E2&"-"&G2 -> 个人-月度交通费（销售/SMO/CO) | C2: EN000101 | D2: 00 | E2: 个人 | F2: 01 | G2: 月度交通费（销售/SMO/CO) | H2: 01 | I2: 燃油费行程问题 | J2: 根据SOP规定，月度交通费报销燃油费需提供每张燃油费的使用时间区间，行程为医院的需具体到科室 | K2: 请根据要求在评论区将行程补充完整
A3: =IF(F3="00","General"&INDEX(问题代码结构!$B$12:$B$20,MATCH($E3,问题代码结构!$C$12:$C$20,0)),D3&F3) -> 0001 | B3: =E3&"-"&G3 -> 个人-月度交通费（销售/SMO/CO) | C3: EN000102 | D3: 00 | E3: 个人 | F3: 01 | G3: 月度交通费（销售/SMO/CO) | H3: 02 | I3: 出租车行程问题 | J3: 根据SOP规定，月度交通费报销出租车费用，需注明具体的行程地点和事由，行程为医院的，应明确注明拜访医院及科室 | K3: 请根据要求补充至HLY评论区
A4: =IF(F4="00","General"&INDEX(问题代码结构!$B$12:$B$20,MATCH($E4,问题代码结构!$C$12:$C$20,0)),D4&F4) -> 0001 | B4: =E4&"-"&G4 -> 个人-月度交通费（销售/SMO/CO) | C4: EN000103 | D4: 00 | E4: 个人 | F4: 01 | G4: 月度交通费（销售/SMO/CO) | H4: 03 | I4: 网约车行程问题 | J4: 根据SOP规定，月度交通费报销网约车费用，行程为医院的，应明确注明拜访医院及科室，并提供事由 | K4: 请根据要求补充至HLY评论区
A5: =IF(F5="00","General"&INDEX(问题代码结构!$B$12:$B$20,MATCH($E5,问题代码结构!$C$12:$C$20,0)),D5&F5) -> 0001 | B5: =E5&"-"&G5 -> 个人-月度交通费（销售/SMO/CO) | C5: EN000104 | D5: 00 | E5: 个人 | F5: 01 | G5: 月度交通费（销售/SMO/CO) | H5: 04 | I5: 单笔超500问题 | J5: 根据SOP规定，单次费用超过人民币500元的长距离陆地交通需要使用指定供应商或有营运资质的网约车，并提供详细行程单 | K5: 请补充提供，无法提供将不予报销
A6: =IF(F6="00","General"&INDEX(问题代码结构!$B$12:$B$20,MATCH($E6,问题代码结构!$C$12:$C$20,0)),D6&F6) -> 0001 | B6: =E6&"-"&G6 -> 个人-月度交通费（销售/SMO/CO) | C6: EN000105 | D6: 00 | E6: 个人 | F6: 01 | G6: 月度交通费（销售/SMO/CO) | H6: 05 | I6: 当月总额超限额 | J6: 根据SOP规定，月度交通费超过标准限额，如需报销，需补充提供部门负责人的特批 | K6: 请提供
A7: =IF(F7="00","General"&INDEX(问题代码结构!$B$12:$B$20,MATCH($E7,问题代码结构!$C$12:$C$20,0)),D7&F7) -> 0002 | B7: =E7&"-"&G7 -> 个人-交通费-市内 | C7: EN000201 | D7: 00 | E7: 个人 | F7: 02 | G7: 交通费-市内 | H7: 01 | I7: 出租车行程问题 | J7: 根据SOP规定，驻地内产生的出租车，公共汽车、地铁等发票，报销时需列明行程和事由 | K7: 请根据要求补充至HLY评论区
A8: =IF(F8="00","General"&INDEX(问题代码结构!$B$12:$B$20,MATCH($E8,问题代码结构!$C$12:$C$20,0)),D8&F8) -> 0002 | B8: =E8&"-"&G8 -> 个人-交通费-市内 | C8: EN000202 | D8: 00 | E8: 个人 | F8: 02 | G8: 交通费-市内 | H8: 02 | I8: 网约车行程问题 | J8: 根据SOP规定，驻地内产生的网约车费用发票，报销时需要提供行程单和事由 | K8: 请根据要求补充至HLY评论区
A9: =IF(F9="00","General"&INDEX(问题代码结构!$B$12:$B$20,MATCH($E9,问题代码结构!$C$12:$C$20,0)),D9&F9) -> 0002 | B9: =E9&"-"&G9 -> 个人-交通费-市内 | C9: EN000203 | D9: 00 | E9: 个人 | F9: 02 | G9: 交通费-市内 | H9: 03 | I9: 单笔超500问题 | J9: 根据SOP规定，单次费用超过人民币500元的长距离陆地交通需要使用指定供应商或有营运资质的网约车，并提供详细行程单 | K9: 请补充提供，无法提供将不予报销
A10: =IF(F10="00","General"&INDEX(问题代码结构!$B$12:$B$20,MATCH($E10,问题代码结构!$C$12:$C$20,0)),D10&F10) -> 0002 | B10: =E10&"-"&G10 -> 个人-交通费-市内 | C10: EN000204 | D10: 00 | E10: 个人 | F10: 02 | G10: 交通费-市内 | H10: 04 | I10: OT打车问题 | J10: 根据SOP规定，工作到晚上19:30分后可以报销回家出租车费，您的OT打车费用不符合要求 | K10: 请确认后为您扣除
A11: =IF(F11="00","General"&INDEX(问题代码结构!$B$12:$B$20,MATCH($E11,问题代码结构!$C$12:$C$20,0)),D11&F11) -> 0003 | B11: =E11&"-"&G11 -> 个人-电话费 | C11: EN000301 | D11: 00 | E11: 个人 | F11: 03 | G11: 电话费 | H11: 01 | I11: 非套餐话费超标&充值发票 | J11: 根据SOP规定，报销话费金额大于350元或发票为充值发票，需要提供话费明细账单； | K11: 请补充上传至HLY评论区
A12: =IF(F12="00","General"&INDEX(问题代码结构!$B$12:$B$20,MATCH($E12,问题代码结构!$C$12:$C$20,0)),D12&F12) -> 0003 | B12: =E12&"-"&G12 -> 个人-电话费 | C12: EN000302 | D12: 00 | E12: 个人 | F12: 03 | G12: 电话费 | H12: 02 | I12: 套餐超350元 | J12: 根据SOP规定，月度套餐费用超过350元的，需解释实际费用需求，并获部门负责人审批 | K12: 请提供
A13: =IF(F13="00","General"&INDEX(问题代码结构!$B$12:$B$20,MATCH($E13,问题代码结构!$C$12:$C$20,0)),D13&F13) -> 0003 | B13: =E13&"-"&G13 -> 个人-电话费 | C13: EN000303 | D13: 00 | E13: 个人 | F13: 03 | G13: 电话费 | H13: 03 | I13: 手机号未备案 | J13: 根据SOP规定，员工需要报销费用的手机号码须在公司备案登记。您的号码未备案，不予报销 | K13: 请提供备案记录或我们帮您扣除该号码下的金额
... A127: =IF(F127="00","General"&INDEX(问题代码结构!$B$12:$B$20,MATCH($E127,问题代码结构!$C$12:$C$20,0)),D127&F127) -> General00 | B127: =E127&"-"&G127 -> 个人-通用 | C127: EN000003 | D127: 00 | E127: 个人 | F127: 00 | G127: 通用 | H127: 03 | I127: 费用逾期 | J127: 根据SOP规定，报销单需在90天内完成审核，您的报销单已超过90天 | K127: 如需报销本次将记录逾期，请回复确认

Sheet 学术
A1: Fee Type Code | B1: Fee Type Description | C1: Problem Code | D1: Meeting Code | E1: 会议类型 | F1: Expense Code | G1: 费用类型 | H1: Issue Code | I1: 问题类型 | J1: SOP描述 | K1: 标准处理方法
A2: =IF(F2="00","General"&INDEX(问题代码结构!$B$12:$B$20,MATCH($E2,问题代码结构!$C$12:$C$20,0)),D2&F2) -> 0101 | B2: =E2&"-"&G2 -> 学术论坛-会议讲课费 | C2: ="MN"&D2&F2&H2 -> MN010101 | D2: 01 | E2: 学术论坛 | F2: 01 | G2: 会议讲课费 | H2: 01 | I2: 非讲者库讲者 | J2: 根据SOP规定，报销讲课费的讲者必须是讲者库中的讲者，且不能在会议结束后特批补入库 | K2: 不符合要求不予支付讲课费
A3: =IF(F3="00","General"&INDEX(问题代码结构!$B$12:$B$20,MATCH($E3,问题代码结构!$C$12:$C$20,0)),D3&F3) -> 0101 | B3: =E3&"-"&G3 -> 学术论坛-会议讲课费 | C3: ="MN"&D3&F3&H3 -> MN010102 | D3: 01 | E3: 学术论坛 | F3: 01 | G3: 会议讲课费 | H3: 02 | I3: 业务约定书不完整 | J3: 根据SOP规定，业务约定书需完整正确的填写，并由HCP签字后将完整原件邮寄至我司 | K3: 请提供
A4: =IF(F4="00","General"&INDEX(问题代码结构!$B$12:$B$20,MATCH($E4,问题代码结构!$C$12:$C$20,0)),D4&F4) -> 0101 | B4: =E4&"-"&G4 -> 学术论坛-会议讲课费 | C4: ="MN"&D4&F4&H4 -> MN010103 | D4: 01 | E4: 学术论坛 | F4: 01 | G4: 会议讲课费 | H4: 03 | I4: 讲者人数超标 | J4: 根据SOP规定，支付讲课费的人数不应超过外部参会总人数的20% | K4: 请确认，并告知需扣除讲课费的HCP姓名
A5: =IF(F5="00","General"&INDEX(问题代码结构!$B$12:$B$20,MATCH($E5,问题代码结构!$C$12:$C$20,0)),D5&F5) -> 0101 | B5: =E5&"-"&G5 -> 学术论坛-会议讲课费 | C5: ="MN"&D5&F5&H5 -> MN010104 | D5: 01 | E5: 学术论坛 | F5: 01 | G5: 会议讲课费 | H5: 04 | I5: 主席和点评嘉宾人数超标 | J5: 根据SOP规定，支付讲课费的主席和点评专家的总数不得超过讲者总数 | K5: 请确认，并告知需扣除讲课费的HCP姓名
A6: =IF(F6="00","General"&INDEX(问题代码结构!$B$12:$B$20,MATCH($E6,问题代码结构!$C$12:$C$20,0)),D6&F6) -> 0101 | B6: =E6&"-"&G6 -> 学术论坛-会议讲课费 | C6: ="MN"&D6&F6&H6 -> MN010105 | D6: 01 | E6: 学术论坛 | F6: 01 | G6: 会议讲课费 | H6: 05 | I6: 讲者未全程参会 | J6: 根据SOP规定，支付讲课费的专家需全程参会，并签到 | K6: 请补充提供签到，不符合要求不予支付讲课费
A7: =IF(F7="00","General"&INDEX(问题代码结构!$B$12:$B$20,MATCH($E7,问题代码结构!$C$12:$C$20,0)),D7&F7) -> 0101 | B7: =E7&"-"&G7 -> 学术论坛-会议讲课费 | C7: ="MN"&D7&F7&H7 -> MN010106 | D7: 01 | E7: 学术论坛 | F7: 01 | G7: 会议讲课费 | H7: 06 | I7: 演讲时长不达标 | J7: 根据SOP规定，学术论坛讲者讲课时间（包括手术演示、讨论问答）需≥20分钟 | K7: 不符合要求不予支付讲课费
A8: =IF(F8="00","General"&INDEX(问题代码结构!$B$12:$B$20,MATCH($E8,问题代码结构!$C$12:$C$20,0)),D8&F8) -> 0101 | B8: =E8&"-"&G8 -> 学术论坛-会议讲课费 | C8: ="MN"&D8&F8&H8 -> MN010107 | D8: 01 | E8: 学术论坛 | F8: 01 | G8: 会议讲课费 | H8: 07 | I8: 点评时长不达标 | J8: 根据SOP规定，学术论坛点评专家限全国级和区域级HCP，且点评时长累计需≥10分钟， | K8: 不符合要求不予支付讲课费
A9: =IF(F9="00","General"&INDEX(问题代码结构!$B$12:$B$20,MATCH($E9,问题代码结构!$C$12:$C$20,0)),D9&F9) -> 0101 | B9: =E9&"-"&G9 -> 学术论坛-会议讲课费 | C9: ="MN"&D9&F9&H9 -> MN010108 | D9: 01 | E9: 学术论坛 | F9: 01 | G9: 会议讲课费 | H9: 08 | I9: 点评专家讲课费标准 | J9: 根据SOP规定，学术论坛点评专家的讲课费支付标准为80%*职级标准 | K9: 将为您扣除差额
A10: =IF(F10="00","General"&INDEX(问题代码结构!$B$12:$B$20,MATCH($E10,问题代码结构!$C$12:$C$20,0)),D10&F10) -> 0101 | B10: =E10&"-"&G10 -> 学术论坛-会议讲课费 | C10: ="MN"&D10&F10&H10 -> MN010109 | D10: 01 | E10: 学术论坛 | F10: 01 | G10: 会议讲课费 | H10: 09 | I10: 主席参会时长 | J10: 根据SOP规定，学术论坛主席限全国级和区域级HCP中主任医师、副主任医师,且原则上应全程参加活动并致辞发言， | K10: 不符合要求不予支付讲课费
A11: =IF(F11="00","General"&INDEX(问题代码结构!$B$12:$B$20,MATCH($E11,问题代码结构!$C$12:$C$20,0)),D11&F11) -> General01 | B11: =E11&"-"&G11 -> 学术论坛-通用 | C11: ="MN"&D11&F11&H11 -> MN010001 | D11: 01 | E11: 学术论坛 | F11: 00 | G11: 通用 | H11: 01 | I11: 会议权限_学术论坛 | J11: 根据SOP规定，学术论坛可举办的组织者岗位为地区业务销售经理及以上、市场、医学、临床运营、市场准入和商务，您无权限举办此类型会议 | K11: 请提供逐级审批至部门负责人的授权邮件并抄送合规
A12: =IF(F12="00","General"&INDEX(问题代码结构!$B$12:$B$20,MATCH($E12,问题代码结构!$C$12:$C$20,0)),D12&F12) -> General01 | B12: =E12&"-"&G12 -> 学术论坛-通用 | C12: ="MN"&D12&F12&H12 -> MN010002 | D12: 01 | E12: 学术论坛 | F12: 00 | G12: 通用 | H12: 02 | I12: 会议议程_变更 | J12: 学会活动变更会议时间、会议地点需提供企业微信变更流程或变更审批邮件 | K12: 请提供
A13: =IF(F13="00","General"&INDEX(问题代码结构!$B$12:$B$20,MATCH($E13,问题代码结构!$C$12:$C$20,0)),D13&F13) -> General01 | B13: =E13&"-"&G13 -> 学术论坛-通用 | C13: ="MN"&D13&F13&H13 -> MN010003 | D13: 01 | E13: 学术论坛 | F13: 00 | G13: 通用 | H13: 03 | I13: 会议议程_不一致 | J13: 会议议程内容与系统填报的实际会议情况不一致 | K13: 请确认并提供更新的会议议程
... A329: =IF(F329="00","General"&INDEX(问题代码结构!$B$12:$B$20,MATCH($E329,问题代码结构!$C$12:$C$20,0)),D329&F329) -> General08 | B329: =E329&"-"&G329 -> 专家咨询会-通用 | C329: ="MN"&D329&F329&H329 -> MN080021 | D329: 08 | E329: 专家咨询会 | F329: 00 | G329: 通用 | H329: 21 | I329: 报销范围_费用 | J329: 根据SOP规定，专家咨询会可报销费用有咨询费、餐饮、住宿、场租、交通 | K329: 额外费用不予报销已为您扣除

Sheet Sheet2
A3: Fee Type Code | B3: Fee Type Description | C3: Meeting Code | D3: 会议类型 | E3: Expense Code | F3: 费用类型 | G3: 计数项:Issue Code
A4: 0001 | B4: 个人-月度交通费（销售/SMO/CO) | C4: 00 | D4: 个人 | E4: 01 | F4: 月度交通费（销售/SMO/CO) | G4: 5
A5: 0002 | B5: 个人-交通费-市内 | C5: 00 | D5: 个人 | E5: 02 | F5: 交通费-市内 | G5: 4
A6: 0003 | B6: 个人-电话费 | C6: 00 | D6: 个人 | E6: 03 | F6: 电话费 | G6: 4
A7: 0004 | B7: 个人-工作餐 | C7: 00 | D7: 个人 | E7: 04 | F7: 工作餐 | G7: 3
A8: 0005 | B8: 个人-办公用品 | C8: 00 | D8: 个人 | E8: 05 | F8: 办公用品 | G8: 2
A9: 0006 | B9: 个人-IT配件 | C9: 00 | D9: 个人 | E9: 06 | F9: IT配件 | G9: 2
A10: 0007 | B10: 个人-快递/货运 | C10: 00 | D10: 个人 | E10: 07 | F10: 快递/货运 | G10: 1
A11: 0008 | B11: 个人-打印/复印 | C11: 00 | D11: 个人 | E11: 08 | F11: 打印/复印 | G11: 3
A12: 0009 | B12: 个人-外部会议/培训 | C12: 00 | D12: 个人 | E12: 09 | F12: 外部会议/培训 | G12: 3
A13: 0010 | B13: 个人-临床杂项 | C13: 00 | D13: 个人 | E13: 10 | F13: 临床杂项 | G13: 4
A14: 0011 | B14: 个人-杂项开支 | C14: 00 | D14: 个人 | E14: 11 | F14: 杂项开支 | G14: 4
A15: 0012 | B15: 个人-机票 | C15: 00 | D15: 个人 | E15: 12 | F15: 机票 | G15: 2
... A34: General00 | B34: 个人-通用 | C34: 00 | D34: 个人 | E34: 00 | F34: 通用 | G34: 3
A35: 总计 | G35: 126

Sheet Sheet1 (3)
A3: Fee Type Code | B3: Fee Type Description | C3: Meeting Code | D3: 会议类型 | E3: Expense Code | F3: 费用类型
A4: 0101 | B4: 学术论坛-会议讲课费 | C4: 01 | D4: 学术论坛 | E4: 01 | F4: 会议讲课费
A5: 0102 | B5: 学术论坛-会议餐费 | C5: 01 | D5: 学术论坛 | E5: 02 | F5: 会议餐费
A6: 0103 | B6: 学术论坛-会议交通费 | C6: 01 | D6: 学术论坛 | E6: 03 | F6: 会议交通费
A7: 0104 | B7: 学术论坛-会议租车费 | C7: 01 | D7: 学术论坛 | E7: 04 | F7: 会议租车费
A8: 0105 | B8: 学术论坛-会议火车票 | C8: 01 | D8: 学术论坛 | E8: 05 | F8: 会议火车票
A9: 0106 | B9: 学术论坛-会议茶歇 | C9: 01 | D9: 学术论坛 | E9: 06 | F9: 会议茶歇
A10: 0107 | B10: 学术论坛-会议场租 | C10: 01 | D10: 学术论坛 | E10: 07 | F10: 会议场租
A11: 0108 | B11: 学术论坛-会议个人车辆 | C11: 01 | D11: 学术论坛 | E11: 08 | F11: 会议个人车辆
A12: 0109 | B12: 学术论坛-会议推广材料制作 | C12: 01 | D12: 学术论坛 | E12: 09 | F12: 会议推广材料制作
A13: 0110 | B13: 学术论坛-会议住宿费 | C13: 01 | D13: 学术论坛 | E13: 10 | F13: 会议住宿费
A14: 0111 | B14: 学术论坛-会议杂项开支 | C14: 01 | D14: 学术论坛 | E14: 11 | F14: 会议杂项开支
... A64: (空白) | B64: (空白) | C64: (空白) | D64: (空白) | E64: (空白) | F64: (空白)
A65: 总计

Sheet Sheet1
A3: 计数项:Issue Code | C3: Meeting Code | D3: 会议类型
C4: 01 | D4: 02 | E4: 03 | F4: 04 | G4: 05 | H4: 06 | I4: 07 | J4: 08 | K4: 总计
A5: Expense Code | B5: 费用类型 | C5: 学术论坛 | D5: 患者教育 | E5: 院内会 | F5: 多学科专家研讨会 | G5: 三方会-支持 | H5: 培训会 | I5: 临床研究-临床试验启动会 | J5: 专家咨询会
A6: 00 | B6: 通用 | C6: 21 | D6: 24 | E6: 18 | F6: 19 | G6: 15 | H6: 19 | I6: 16 | J6: 21 | K6: 153
A7: 01 | B7: 会议讲课费 | C7: 9 | D7: 10 | F7: 8 | H7: 8 | K7: 35
A8: 02 | B8: 会议餐费 | C8: 6 | D8: 6 | E8: 6 | F8: 6 | G8: 6 | H8: 6 | I8: 6 | K8: 42
A9: 03 | B9: 会议交通费 | C9: 1 | F9: 1 | G9: 1 | H9: 1 | K9: 4
A10: 04 | B10: 会议租车费 | C10: 3 | F10: 3 | G10: 3 | H10: 3 | K10: 12
A11: 05 | B11: 会议火车票 | C11: 1 | F11: 1 | G11: 1 | H11: 1 | K11: 4
A12: 06 | B12: 会议茶歇 | C12: 4 | D12: 4 | E12: 3 | F12: 4 | G12: 4 | H12: 4 | I12: 4 | K12: 27
A13: 07 | B13: 会议场租 | C13: 2 | F13: 2 | G13: 2 | H13: 2 | K13: 8
A14: 08 | B14: 会议个人车辆 | C14: 2 | F14: 2 | G14: 2 | H14: 2 | K14: 8
A15: 09 | B15: 会议推广材料制作 | C15: 2 | F15: 2 | G15: 2 | I15: 2 | K15: 8
A16: 10 | B16: 会议住宿费 | C16: 3 | F16: 3 | G16: 3 | H16: 3 | K16: 12
A17: 11 | B17: 会议杂项开支 | C17: 2 | F17: 2 | G17: 2 | H17: 2 | I17: 2 | K17: 10
A18: 12 | B18: 专家咨询费 | J18: 5 | K18: 5
A19: 总计 | C19: 56 | D19: 44 | E19: 27 | F19: 53 | G19: 41 | H19: 51 | I19: 30 | J19: 26 | K19: 328
C21: =COUNTA(C7:C18)*C6+SUM(C7:C18) -> 266 | D21: =COUNTA(D7:D18)*D6+SUM(D7:D18) -> 92 | E21: =COUNTA(E7:E18)*E6+SUM(E7:E18) -> 45 | F21: =COUNTA(F7:F18)*F6+SUM(F7:F18) -> 243 | G21: =COUNTA(G7:G18)*G6+SUM(G7:G18) -> 176 | H21: =COUNTA(H7:H18)*H6+SUM(H7:H18) -> 222 | I21: =COUNTA(I7:I18)*I6+SUM(I7:I18) -> 78 | J21: =COUNTA(J7:J18)*J6+SUM(J7:J18) -> 26 | K21: =SUM(C21:J21) -> 1148
A23: 计数项:Issue Code | C23: Meeting Code | D23: 会议类型
C24: 01 | D24: 02 | E24: 03 | F24: 04 | G24: 05 | H24: 06 | I24: 07 | J24: 08 | K24: 总计
A25: Expense Code | B25: 费用类型 | C25: 学术论坛 | D25: 患者教育 | E25: 院内会 | F25: 多学科专家研讨会 | G25: 三方会-支持 | H25: 培训会 | I25: 临床研究-临床试验启动会 | J25: 专家咨询会
A26: 01 | B26: 会议讲课费 | C26: 30 | D26: 34 | F26: 27 | H26: 27 | K26: 118
A27: 02 | B27: 会议餐费 | C27: 27 | D27: 30 | E27: 24 | F27: 25 | G27: 21 | H27: 25 | I27: 22 | K27: 174
A28: 03 | B28: 会议交通费 | C28: 22 | F28: 20 | G28: 16 | H28: 20 | K28: 78
A29: 04 | B29: 会议租车费 | C29: 24 | F29: 22 | G29: 18 | H29: 22 | K29: 86
A30: 05 | B30: 会议火车票 | C30: 22 | F30: 20 | G30: 16 | H30: 20 | K30: 78
A31: 06 | B31: 会议茶歇 | C31: 25 | D31: 28 | E31: 21 | F31: 23 | G31: 19 | H31: 23 | I31: 20 | K31: 159
A32: 07 | B32: 会议场租 | C32: 23 | F32: 21 | G32: 17 | H32: 21 | K32: 82
A33: 08 | B33: 会议个人车辆 | C33: 23 | F33: 21 | G33: 17 | H33: 21 | K33: 82
A34: 09 | B34: 会议推广材料制作 | C34: 23 | F34: 21 | G34: 17 | I34: 18 | K34: 79
A35: 10 | B35: 会议住宿费 | C35: 24 | F35: 22 | G35: 18 | H35: 22 | K35: 86
A36: 11 | B36: 会议杂项开支 | C36: 23 | F36: 21 | G36: 17 | H36: 21 | I36: 18 | K36: 100
A37: 12 | B37: 专家咨询费 | J37: 26 | K37: 26
A38: 总计 | C38: 266 | D38: 92 | E38: 45 | F38: 243 | G38: 176 | H38: 222 | I38: 78 | J38: 26 | K38: 1148

Sheet Sheet1 (2)
A3: Meeting Code | B3: 会议类型 | C3: Expense Code | D3: 费用类型 | E3: 计数项:Issue Code
A4: 01 | B4: 学术论坛 | C4: 00 | D4: 通用 | E4: 21
C5: 01 | D5: 会议讲课费 | E5: 9
C6: 02 | D6: 会议餐费 | E6: 6
C7: 03 | D7: 会议交通费 | E7: 1
C8: 04 | D8: 会议租车费 | E8: 3
C9: 05 | D9: 会议火车票 | E9: 1
C10: 06 | D10: 会议茶歇 | E10: 4
C11: 07 | D11: 会议场租 | E11: 2
C12: 08 | D12: 会议个人车辆 | E12: 2
C13: 09 | D13: 会议推广材料制作 | E13: 2
C14: 10 | D14: 会议住宿费 | E14: 3
C15: 11 | D15: 会议杂项开支 | E15: 2
A16: 02 | B16: 患者教育 | C16: 00 | D16: 通用 | E16: 24
C17: 01 | D17: 会议讲课费 | E17: 10
C18: 02 | D18: 会议餐费 | E18: 6
C19: 06 | D19: 会议茶歇 | E19: 4
A20: 03 | B20: 院内会 | C20: 00 | D20: 通用 | E20: 18
C21: 02 | D21: 会议餐费 | E21: 6
C22: 06 | D22: 会议茶歇 | E22: 3
A23: 04 | B23: 多学科专家研讨会 | C23: 00 | D23: 通用 | E23: 19
C24: 01 | D24: 会议讲课费 | E24: 8
C25: 02 | D25: 会议餐费 | E25: 6
C26: 03 | D26: 会议交通费 | E26: 1
C27: 04 | D27: 会议租车费 | E27: 3
C28: 05 | D28: 会议火车票 | E28: 1
C29: 06 | D29: 会议茶歇 | E29: 4
C30: 07 | D30: 会议场租 | E30: 2
C31: 08 | D31: 会议个人车辆 | E31: 2
C32: 09 | D32: 会议推广材料制作 | E32: 2
C33: 10 | D33: 会议住宿费 | E33: 3
C34: 11 | D34: 会议杂项开支 | E34: 2
A35: 05 | B35: 三方会-支持 | C35: 00 | D35: 通用 | E35: 15
C36: 02 | D36: 会议餐费 | E36: 6
C37: 03 | D37: 会议交通费 | E37: 1
C38: 04 | D38: 会议租车费 | E38: 3
C39: 05 | D39: 会议火车票 | E39: 1
C40: 06 | D40: 会议茶歇 | E40: 4
C41: 07 | D41: 会议场租 | E41: 2
C42: 08 | D42: 会议个人车辆 | E42: 2
...
